06:57:05 PM:DEBUG [logger_base.py:16] Mensaje a nivel debug
06:57:05 PM:INFO [logger_base.py:17] Mensaje a nivel info
06:57:05 PM:WARNING [logger_base.py:18] Mensaje a nivel warning
06:57:05 PM:ERROR [logger_base.py:19] Mensaje a nivel error
06:57:05 PM:CRITICAL [logger_base.py:20] Mensaje a nivel critical
01:20:48 AM:DEBUG [Persona.py:48] 
            Id Persona: 1,
            Nombre: Juan,
            Apellido: Perez,
            Email: jperez@mail.com
        
01:23:06 AM:DEBUG [Persona.py:48] 
            Id Persona: 1,
            Nombre: Juan,
            Apellido: Perez,
            Email: jperez@mail.com
        
01:24:42 AM:DEBUG [Persona.py:48] 
            Id Persona: 1,
            Nombre: Juan,
            Apellido: Perez,
            Email: jperez@mail.com
        
01:24:42 AM:DEBUG [Persona.py:51] 
            Id Persona: Jose,
            Nombre: Lepez,
            Apellido: ljose@mail.com,
            Email: None
        
01:25:21 AM:DEBUG [Persona.py:48] 
            Id Persona: 1,
            Nombre: Juan,
            Apellido: Perez,
            Email: jperez@mail.com
        
01:25:21 AM:DEBUG [Persona.py:51] 
            Id Persona: None,
            Nombre: Jose,
            Apellido: Lepez,
            Email: ljose@mail.com
        
01:26:29 AM:DEBUG [Persona.py:48] 
            Id Persona: 1,
            Nombre: Juan,
            Apellido: Perez,
            Email: jperez@mail.com
        
01:26:29 AM:DEBUG [Persona.py:51] 
            Id Persona: None,
            Nombre: Jose,
            Apellido: Lepez,
            Email: ljose@mail.com
        
01:26:29 AM:DEBUG [Persona.py:53] 
            Id Persona: 1,
            Nombre: None,
            Apellido: None,
            Email: None
        
02:47:52 AM:DEBUG [conexion.py:22] Conexión Exitosa: <connection object at 0x0000027B72292790; dsn: 'user=postgres password=xxx dbname=test_bd host=127.0.0.1 port=5432', closed: 0>
02:49:27 AM:ERROR [conexion.py:25] Ocurrio un error: connection to server at "127.0.0.1", port 5432 failed: FATAL:  password authentication failed for user "postgre"

02:50:38 AM:DEBUG [conexion.py:22] Conexión Exitosa: <connection object at 0x00000225A3952790; dsn: 'user=postgres password=xxx dbname=test_bd host=127.0.0.1 port=5432', closed: 0>
02:50:38 AM:ERROR [conexion.py:38] Ocurrio un error: 'NoneType' object has no attribute 'cursor'
02:54:46 AM:DEBUG [conexion.py:22] Conexión Exitosa: <connection object at 0x0000022609142790; dsn: 'user=postgres password=xxx dbname=test_bd host=127.0.0.1 port=5432', closed: 0>
02:54:46 AM:ERROR [conexion.py:38] Ocurrio un error: 'NoneType' object has no attribute 'cursor'
02:55:06 AM:DEBUG [conexion.py:22] Conexión Exitosa: <connection object at 0x0000022111862790; dsn: 'user=postgres password=xxx dbname=test_bd host=127.0.0.1 port=5432', closed: 0>
02:55:06 AM:DEBUG [conexion.py:35] Se abrió correctamente el cursor: <cursor object at 0x00000221136075A0; closed: 0>
07:17:49 PM:DEBUG [conexion.py:24] Conexión Exitosa: <connection object at 0x0000018AE3AB2790; dsn: 'user=postgres password=xxx dbname=test_bd host=127.0.0.1 port=5432', closed: 0>
07:17:49 PM:DEBUG [conexion.py:38] Se abrió correctamente el cursor: <cursor object at 0x0000018AE58175A0; closed: 0>
07:20:31 PM:DEBUG [conexion.py:24] Conexión Exitosa: <connection object at 0x00000134E5792790; dsn: 'user=postgres password=xxx dbname=test_bd host=127.0.0.1 port=5432', closed: 0>
07:20:31 PM:DEBUG [conexion.py:38] Se abrió correctamente el cursor: <cursor object at 0x00000134E74F75A0; closed: 0>
07:20:40 PM:DEBUG [conexion.py:24] Conexión Exitosa: <connection object at 0x0000026040F12790; dsn: 'user=postgres password=xxx dbname=test_bd host=127.0.0.1 port=5432', closed: 0>
07:20:40 PM:DEBUG [conexion.py:38] Se abrió correctamente el cursor: <cursor object at 0x0000026042CA75A0; closed: 0>
07:24:24 PM:DEBUG [conexion.py:24] Conexión Exitosa: <connection object at 0x0000026B3A1E2790; dsn: 'user=postgres password=xxx dbname=test_bd host=127.0.0.1 port=5432', closed: 0>
07:24:24 PM:DEBUG [conexion.py:38] Se abrió correctamente el cursor: <cursor object at 0x0000026B3C3075A0; closed: 0>
07:32:44 PM:DEBUG [conexion.py:24] Conexión Exitosa: <connection object at 0x00000177026028A0; dsn: 'user=postgres password=xxx dbname=test_bd host=127.0.0.1 port=5432', closed: 0>
07:32:44 PM:DEBUG [conexion.py:38] Se abrió correctamente el cursor: <cursor object at 0x0000017704363680; closed: 0>
07:33:46 PM:DEBUG [conexion.py:24] Conexión Exitosa: <connection object at 0x0000028CE69628A0; dsn: 'user=postgres password=xxx dbname=test_bd host=127.0.0.1 port=5432', closed: 0>
07:33:46 PM:DEBUG [conexion.py:38] Se abrió correctamente el cursor: <cursor object at 0x0000028CE8A93680; closed: 0>
07:35:38 PM:DEBUG [conexion.py:24] Conexión Exitosa: <connection object at 0x0000021D207F28A0; dsn: 'user=postgres password=xxx dbname=test_bd host=127.0.0.1 port=5432', closed: 0>
07:35:38 PM:DEBUG [conexion.py:38] Se abrió correctamente el cursor: <cursor object at 0x0000021D228D3680; closed: 0>
07:36:42 PM:DEBUG [conexion.py:24] Conexión Exitosa: <connection object at 0x0000017010B328A0; dsn: 'user=postgres password=xxx dbname=test_bd host=127.0.0.1 port=5432', closed: 0>
07:36:42 PM:DEBUG [conexion.py:38] Se abrió correctamente el cursor: <cursor object at 0x0000017012C63680; closed: 0>
07:49:34 PM:DEBUG [conexion.py:24] Conexión Exitosa: <connection object at 0x0000025EB0FA1690; dsn: 'user=postgres password=xxx dbname=test_bd host=127.0.0.1 port=5432', closed: 0>
07:49:34 PM:DEBUG [conexion.py:38] Se abrió correctamente el cursor: <cursor object at 0x0000025EB2EC52A0; closed: 0>
08:20:10 PM:DEBUG [conexion.py:24] Conexión Exitosa: <connection object at 0x0000018F87272790; dsn: 'user=postgres password=xxx dbname=test_bd host=127.0.0.1 port=5432', closed: 0>
08:20:10 PM:DEBUG [conexion.py:38] Se abrió correctamente el cursor: <cursor object at 0x0000018F893775A0; closed: 0>
08:41:56 PM:DEBUG [conexion.py:24] Conexión Exitosa: <connection object at 0x000001C1967D1690; dsn: 'user=postgres password=xxx dbname=test_bd host=127.0.0.1 port=5432', closed: 0>
08:41:56 PM:DEBUG [conexion.py:38] Se abrió correctamente el cursor: <cursor object at 0x000001C1986A5380; closed: 0>
12:03:43 AM:ERROR [conexion.py:42] Ocurrio un error al obtener el pool: invalid dsn: invalid connection option "bost"

12:05:49 AM:ERROR [conexion.py:42] Ocurrio un error al obtener el pool: invalid dsn: invalid connection option "bost"

